<?xml version="1.0"?>
<robot xmlns:xacro="http://www.ros.org/wiki/xacro"  >

    <!--ROS2_CONTROL MACROS-->

    <!--Joint Creator-->

    <xacro:macro name="joint_creator" params="name">
        <joint name="${name}">
            <command_interface name="velocity">
                <param name="min">-10</param>
                <param name="max">10</param>
            </command_interface>

            <state_interface name="velocity"/>
            <state_interface name="position"/>

        </joint>
    </xacro:macro>

    <!--ROBOT_CORE MACROS-->

    <!--Encoder Wheel Macro-->

    <xacro:macro name="wheel" params="name origin direction axis">

        <joint name="${name}_joint" type="continuous">
            <parent link="base_link" />
            <child link="${name}" />
            <origin xyz="${origin}" rpy="${direction}${pi/2} 0 0" />
            <axis xyz="0 0 ${axis}1" />
        </joint>

        <link name="${name}">

            <visual>
                <material name="blue"/>
                <geometry>
                    <cylinder radius="${wheel_radius}" length="${wheel_length}" />
                </geometry>
            </visual>

            <collision>
                <geometry>
                    <cylinder radius="${wheel_radius}" length="${wheel_length}" />
                </geometry>
            </collision>

            <xacro:inertial_cylinder mass="0.5" length="${wheel_length}" radius="${wheel_radius}">
                <origin xyz="0 0 0" rpy="0 0 0"/>
            </xacro:inertial_cylinder>

        
        </link>

        <gazebo reference="${name}">
            <material>Gazebo/Blue</material>   
        </gazebo>
    </xacro:macro>

    <!--NOT Enconder Wheel Macro-->
    <xacro:macro name="dummy_wheel" params="name origin direction axis">

        <joint name="${name}_joint" type="continuous">
            <parent link="base_link" />
            <child link="${name}" />
            <origin xyz="${origin}" rpy="${direction}${pi/2} 0 0" />
            <axis xyz="0 0 ${axis}1" />
        </joint>

        <link name="${name}">

            <visual>
                <material name="orange"/>
                <geometry>
                    <cylinder radius="${wheel_radius}" length="${wheel_length}" />
                </geometry>
            </visual>

            <collision>
                <geometry>
                    <cylinder radius="${wheel_radius}" length="${wheel_length}" />
                </geometry>
            </collision>

            <xacro:inertial_cylinder mass="0.5" length="${wheel_length}" radius="${wheel_radius}">
                <origin xyz="0 0 0" rpy="0 0 0"/>
            </xacro:inertial_cylinder>

        
        </link>

        <gazebo reference="${name}">
            <material>Gazebo/Orange</material>   
            <mu1 value="0.001"/>   
            <mu2 value="0.001"/>  
        </gazebo>
    </xacro:macro>


    <!--Inertial Macros-->

    <xacro:macro name="inertial_sphere" params="mass radius *origin">
        <inertial>
            <xacro:insert_block name="origin"/>
            <mass value="${mass}" />
            <inertia ixx="${(2/5) * mass * (radius*radius)}" ixy="0.0" ixz="0.0"
                    iyy="${(2/5) * mass * (radius*radius)}" iyz="0.0"
                    izz="${(2/5) * mass * (radius*radius)}" />
        </inertial>
    </xacro:macro>  


    <xacro:macro name="inertial_box" params="mass x y z *origin">
        <inertial>
            <xacro:insert_block name="origin"/>
            <mass value="${mass}" />
            <inertia ixx="${(1/12) * mass * (y*y+z*z)}" ixy="0.0" ixz="0.0"
                    iyy="${(1/12) * mass * (x*x+z*z)}" iyz="0.0"
                    izz="${(1/12) * mass * (x*x+y*y)}" />
        </inertial>
    </xacro:macro>


    <xacro:macro name="inertial_cylinder" params="mass length radius *origin">
        <inertial>
            <xacro:insert_block name="origin"/>
            <mass value="${mass}" />
            <inertia ixx="${(1/12) * mass * (3*radius*radius + length*length)}" ixy="0.0" ixz="0.0"
                    iyy="${(1/12) * mass * (3*radius*radius + length*length)}" iyz="0.0"
                    izz="${(1/2) * mass * (radius*radius)}" />
        </inertial>
    </xacro:macro>

</robot>