<?xml version="1.0" ?>
<!-- =================================================================================== -->
<!-- |    This document was autogenerated by xacro from arm.urdf.xacro                 | -->
<!-- |    EDITING THIS FILE BY HAND IS NOT RECOMMENDED                                 | -->
<!-- =================================================================================== -->
<robot name="robot_arm">
  <!--ROS2_CONTROL MACROS-->
  <!--Joint Creator-->
  <!--ROBOT_CORE MACROS-->
  <!--Encoder Wheel Macro-->
  <!--Inertial Macros-->
  <!--Arm Inertial Macros-->
  <!--DEFINING MY OWN MACROS CUZ WHOEVER DID THE ARM IS STUPID-->
  <material name="white">
    <color rgba="1 1 1 1"/>
  </material>
  <material name="orange">
    <color rgba="1 0.3 0.1 1"/>
  </material>
  <material name="blue">
    <color rgba="0.2 0.2 1 1"/>
  </material>
  <material name="black">
    <color rgba="0 0 0 1"/>
  </material>
  
  <!--Dummy Link-->
  <link name="base_link"/>
  <joint name="dummy_joint" type="fixed">
    <parent link="base_link"/>
    <child link="arm_a1"/>
  </joint>
  <!--Arm Links-->
  <!--Arm 1-->
  <link name="arm_a1">
    <visual>
      <origin rpy="1.5707963267948966 0 0" xyz="0 0 0"/>
      <geometry>
        <mesh filename="file:///home/joas329/Desktop/rover_simulation/install/my_bot/share/my_bot/description/mesh/ARM-A01.STL"/>
      </geometry>
      <material name="white"/>
    </visual>
    <inertial>
      <mass value="3.8185"/>
      <origin rpy="0 0 0" xyz="-0.085057488 -7.874e-06 -0.19600748199999998"/>
      <inertia ixx="70910.68402480001" ixy="-54.50901710000001" ixz="-1641.1270861" iyy="48858.5770933" iyz="2.6435432000000003" izz="28334.269394600004"/>
    </inertial>
    <collision>
      <origin rpy="1.5707963267948966 0 0" xyz="0 0 0"/>
      <geometry>
        <mesh filename="file:///home/joas329/Desktop/rover_simulation/install/my_bot/share/my_bot/description/mesh/ARM-A01.STL"/>
      </geometry>
    </collision>
  </link>
  <joint name="arm_j1" type="revolute">
    <origin rpy="0 0 0" xyz="-0.08889999999999999 0.0 0.013134974999999998"/>
    <parent link="arm_a1"/>
    <child link="arm_a2"/>
    <axis xyz="0 0 1"/>
    <limit effort="400000.0" lower="-3.141592653589793" upper="3.141592653589793" velocity="300000.0"/>
  </joint>
  <!--Arm 2-->
  <link name="arm_a2">
    <visual>
      <origin rpy="1.5707963267948966 0 0" xyz="0 0 0"/>
      <geometry>
        <mesh filename="file:///home/joas329/Desktop/rover_simulation/install/my_bot/share/my_bot/description/mesh/ARM-A02.STL"/>
      </geometry>
      <material name="white"/>
    </visual>
    <inertial>
      <mass value="3.6524"/>
      <origin rpy="0 0 0" xyz="0.0 -0.0009649460000000001 0.06909562"/>
      <inertia ixx="15137.097100000003" ixy="0.0" ixz="0.0" iyy="10260.60358" iyz="-100.4476109" izz="7660.6507200000015"/>
    </inertial>
    <collision>
      <origin rpy="1.5707963267948966 0 0" xyz="0 0 0"/>
      <geometry>
        <mesh filename="file:///home/joas329/Desktop/rover_simulation/install/my_bot/share/my_bot/description/mesh/ARM-A02.STL"/>
      </geometry>
    </collision>
  </link>
  <joint name="arm_j2" type="revolute">
    <origin rpy="0 0 0" xyz="0.0 0.0 0.09525"/>
    <parent link="arm_a2"/>
    <child link="arm_a3"/>
    <axis xyz="0 1 0"/>
    <limit effort="125000.0" lower="-2.356194490192345" upper="0.2617993877991494" velocity="300000.0"/>
  </joint>
  <!--Arm 3-->
  <link name="arm_a3">
    <visual>
      <origin rpy="1.5707963267948966 0 0" xyz="0 0 0"/>
      <geometry>
        <mesh filename="file:///home/joas329/Desktop/rover_simulation/install/my_bot/share/my_bot/description/mesh/ARM-A03.STL"/>
      </geometry>
      <material name="white"/>
    </visual>
    <inertial>
      <mass value="6.5626"/>
      <origin rpy="0 0 0" xyz="0.22864571999999997 -0.11213084 -9.397999999999999e-06"/>
      <inertia ixx="46091.86306000001" ixy="17.3798904" ixz="108.75789830000001" iyy="327229.8701" iyz="3.4731658000000003" izz="369329.7017"/>
    </inertial>
    <collision>
      <origin rpy="1.5707963267948966 0 0" xyz="0 0 0"/>
      <geometry>
        <mesh filename="file:///home/joas329/Desktop/rover_simulation/install/my_bot/share/my_bot/description/mesh/ARM-A03.STL"/>
      </geometry>
    </collision>
  </link>
  <joint name="arm_j3" type="revolute">
    <origin rpy="0 0 0" xyz="0.4572 0.0 0.0"/>
    <parent link="arm_a3"/>
    <child link="arm_a4"/>
    <axis xyz="0 1 0"/>
    <limit effort="800000.0" lower="-2.0943951023931953" upper="2.0943951023931953" velocity="300000.0"/>
  </joint>
  <!--Arm 4-->
  <link name="arm_a4">
    <visual>
      <origin rpy="1.5707963267948966 0 0" xyz="0 0 0"/>
      <geometry>
        <mesh filename="file:///home/joas329/Desktop/rover_simulation/install/my_bot/share/my_bot/description/mesh/ARM-A04.STL"/>
      </geometry>
      <material name="white"/>
    </visual>
    <inertial>
      <mass value="5.284"/>
      <origin rpy="0 0 0" xyz="0.12684252000000001 -0.00048006 0.0"/>
      <inertia ixx="12489.054252000002" ixy="-795.031556" ixz="0.421842" iyy="159821.802093" iyz="0.07030700000000001" izz="168834.66734400002"/>
    </inertial>
    <collision>
      <origin rpy="1.5707963267948966 0 0" xyz="0 0 0"/>
      <geometry>
        <mesh filename="file:///home/joas329/Desktop/rover_simulation/install/my_bot/share/my_bot/description/mesh/ARM-A04.STL"/>
      </geometry>
    </collision>
  </link>
  <joint name="arm_j4" type="continuous">
    <origin rpy="0 0 0" xyz="0.113949999938 0.0 0.0"/>
    <parent link="arm_a4"/>
    <child link="arm_a5"/>
    <axis xyz="1 0 0"/>
    <limit effort="300000.0" lower="-3.141592653589793" upper="3.141592653589793" velocity="300000.0"/>
  </joint>
  <!--Arm 5-->
  <link name="arm_a5">
    <visual>
      <origin rpy="1.5707963267948966 0 0" xyz="0 0 0"/>
      <geometry>
        <mesh filename="file:///home/joas329/Desktop/rover_simulation/install/my_bot/share/my_bot/description/mesh/ARM-A05.STL"/>
      </geometry>
      <material name="white"/>
    </visual>
    <inertial>
      <mass value="2.8972"/>
      <origin rpy="0 0 0" xyz="0.37643561999999997 -0.00669036 0.0"/>
      <inertia ixx="13825.027866" ixy="1241.1294710000002" ixz="1.2655260000000002" iyy="21563.719356" iyz="0.7030700000000001" izz="30668.264935000003"/>
    </inertial>
    <collision>
      <origin rpy="1.5707963267948966 0 0" xyz="0 0 0"/>
      <geometry>
        <mesh filename="file:///home/joas329/Desktop/rover_simulation/install/my_bot/share/my_bot/description/mesh/ARM-A05.STL"/>
      </geometry>
    </collision>
  </link>
  <joint name="arm_j5" type="revolute">
    <origin rpy="0 0 0" xyz="0.43815 0.0 0.0"/>
    <parent link="arm_a5"/>
    <child link="arm_a6"/>
    <axis xyz="0 1 0"/>
    <limit effort="300000.0" lower="-1.5707963267948966" upper="1.5707963267948966" velocity="300000.0"/>
  </joint>
  <!--Arm 6-->
  <link name="arm_a6">
    <visual>
      <origin rpy="1.5707963267948966 0 0" xyz="0 0 0"/>
      <geometry>
        <mesh filename="file:///home/joas329/Desktop/rover_simulation/install/my_bot/share/my_bot/description/mesh/ARM-A06.STL"/>
      </geometry>
      <material name="white"/>
    </visual>
    <inertial>
      <mass value="2.2545"/>
      <origin rpy="0 0 0" xyz="0.040927019999999995 -0.0006096 -0.00035052"/>
      <inertia ixx="5784.789653000001" ixy="-61.940467000000005" ixz="29.177405000000004" iyy="4394.398421000001" iyz="-0.5624560000000001" izz="6329.106447000001"/>
    </inertial>
    <collision>
      <origin rpy="1.5707963267948966 0 0" xyz="0 0 0"/>
      <geometry>
        <mesh filename="file:///home/joas329/Desktop/rover_simulation/install/my_bot/share/my_bot/description/mesh/ARM-A06.STL"/>
      </geometry>
    </collision>
  </link>
  <joint name="arm_j6" type="revolute">
    <origin rpy="0 0 0" xyz="0.075849999938 0.0 0.0"/>
    <parent link="arm_a6"/>
    <child link="arm_a7"/>
    <axis xyz="1 0 0"/>
    <limit effort="300000.0" lower="-1.5707963267948966" upper="1.5707963267948966" velocity="300000.0"/>
  </joint>
  <!--Arm 7-->
  <link name="arm_a7">
    <inertial>
      <mass value="0.454"/>
      <origin rpy="0 0 0" xyz="0.0 0.0 0.0"/>
      <inertia ixx="7.0307" ixy="0.0" ixz="-0.0" iyy="7.0307" iyz="-0.0" izz="7.0307"/>
    </inertial>
    <collision>
      <origin rpy="0 0 0" xyz="0.0 0.0 0.0"/>
      <geometry>
        <box size="0.01 0.01 0.01"/>
      </geometry>
    </collision>
  </link>
  <!--Defining ROS2 Control Joints-->
  <ros2_control name="GazeboSystem" type="system">
    <hardware>
      <plugin>gazebo_ros2_control/GazeboSystem</plugin>
    </hardware>
    <joint name="arm_j1">
      <command_interface name="effort"/>
      <state_interface name="position">
        <param name="initial_value">0.0</param>
      </state_interface>
      <state_interface name="velocity"/>
    </joint>
    <joint name="arm_j2">
      <command_interface name="effort"/>
      <state_interface name="position">
        <param name="initial_value">0.0</param>
      </state_interface>
      <state_interface name="velocity"/>
    </joint>
    <joint name="arm_j3">
      <command_interface name="effort"/>
      <state_interface name="position">
        <param name="initial_value">0.0</param>
      </state_interface>
      <state_interface name="velocity"/>
    </joint>
    <joint name="arm_j4">
      <command_interface name="effort"/>
      <state_interface name="position">
        <param name="initial_value">0.0</param>
      </state_interface>
      <state_interface name="velocity"/>
    </joint>
    <joint name="arm_j5">
      <command_interface name="effort"/>
      <state_interface name="position">
        <param name="initial_value">0.0</param>
      </state_interface>
      <state_interface name="velocity"/>
    </joint>
    <joint name="arm_j6">
      <command_interface name="effort"/>
      <state_interface name="position">
        <param name="initial_value">0.0</param>
      </state_interface>
      <state_interface name="velocity"/>
    </joint>
  </ros2_control>
  <gazebo>
    <plugin filename="libgazebo_ros2_control.so" name="gazebo_ros2_control">
      <parameters> /home/joas329/Desktop/rover_simulation/install/my_bot/share/my_bot/config/arm_controllers.yaml</parameters>
    </plugin>
  </gazebo>
</robot>
